Workbook

Sheet Raw Messy Data
A1: Invoice | B1: StockCode | C1: Description | D1: Quantity | E1: InvoiceDate | F1: Price | G1: Customer ID | H1: Country
A2: 503181 | B2: 84792 | C2: ENCHANTED BIRD COATHANGER 5 HOOK | D2: 4 | E2: 40267.599 | F2: 4.65 | H2: United Kingdom
A3: 528386 | B3: 22318 | C3: FIVE HEART HANGING DECORATION | D3: 6 | E3: 40472.772 | F3: 2.95 | G3: 14911 | H3: EIRE
A4: 498594 | B4: 21173 | C4: LOO ROLL METAL SIGN | D4: 1 | E4: 40230.658 | F4: 1.65 | G4: 16797 | H4: United Kingdom
A5: 503245 | B5: 21777 | C5: RECIPE BOX WITH METAL HEART | D5: 2 | E5: 40268.411 | F5: 7.95 | G5: 15216 | H5: United Kingdom
A6: 505756 | B6: 84836 | C6: ZINC METAL HEART DECORATION | D6: 12 | E6: 40294.408 | F6: 1.25 | G6: 14677 | H6: United Kingdom
A7: 496975 | B7: 21559 | C7: STRAWBERRY LUNCHBOX WITH CUTLERY | D7: 6 | E7: 40214.385 | F7: 2.55 | G7: 12712 | H7: Germany
A8: 491584 | B8: 85107 | C8: CUT GLASS T-LIGHT HOLDER OCTAGON | D8: 12 | E8: 40158.538 | F8: 2.55 | G8: 12854 | H8: United Kingdom
A9: 516478 | B9: 22575 | C9: METAL MERRY CHRISTMAS WREATH | D9: 1 | E9: 40379.722 | F9: 1.95 | G9: 17576 | H9: United Kingdom
A10: 502588 | B10: 22083 | C10: PAPER CHAIN KIT RETRO SPOT | D10: 2 | E10: 40262.53 | F10: 2.95 | G10: 16550 | H10: United Kingdom
A11: 515335 | B11: 85014B | C11: RED/WHITE DOTS RUFFLED UMBRELLA | D11: 1 | E11: 40370.597 | F11: 5.95 | G11: 14606 | H11: United Kingdom
A12: 525065 | B12: 21156 | C12: RETROSPOT CHILDRENS APRON | D12: 1 | E12: 40454.603 | F12: 1.95 | G12: 16799 | H12: United Kingdom
A13: 535349 | B13: 84946 | C13: ANTIQUE SILVER TEA GLASS ETCHED | D13: 24 | E13: 40507.703 | F13: 1.25 | G13: 18245 | H13: United Kingdom
A14: 521949 | B14: 82484 | C14: WOOD BLACK BOARD ANT WHITE FINISH | D14: 3 | E14: 40430.719 | F14: 6.45 | G14: 15150 | H14: United Kingdom
A15: 514876 | B15: 22519 | C15: CHILDS GARDEN BRUSH PINK | D15: 36 | E15: 40366.44 | F15: 1.85 | G15: 17511 | H15: United Kingdom
A16: 521162 | B16: 22561 | C16: WOODEN SCHOOL COLOURING SET | D16: 12 | E16: 40423.599 | F16: 1.65 | G16: 12598 | H16: France
A17: 506572 | B17: 20798 | C17: CLEAR MILKSHAKE GLASS | D17: 4 | E17: 40298.549 | F17: 2.1 | G17: 16374 | H17: United Kingdom
A18: 505974 | B18: 48188 | C18: DOOR MAT WELCOME PUPPIES | D18: 1 | E18: 40294.754 | F18: 7.49 | G18: 17449 | H18: United Kingdom
A19: 491622 | B19: 10125 | C19: MINI FUNKY DESIGN TAPES | D19: 1 | E19: 40158.597 | F19: 0.85 | G19: 13415 | H19: U.K.
A20: 509982 | B20: 21696 | C20: SMALL SILVER TRELLIS CANDLEPOT | D20: 6 | E20: 40324.603 | F20: 2.95 | G20: 12924 | H20: United Kingdom
A21: 524611 | B21: 85114B | C21: IVORY ENCHANTED FOREST PLACEMAT | D21: 6 | E21: 40451.401 | F21: 1.65 | G21: 13078 | H21: United Kingdom
A22: 501906 | B22: 22413 | C22: METAL SIGN TAKE IT OR LEAVE IT | D22: 12 | E22: 40258.668 | F22: 2.95 | G22: 17340 | H22: United Kingdom
A23: 505708 | B23: 20979 | C23: 36 PENCILS TUBE RED SPOTTY | D23: 1 | E23: 40293.51 | F23: 1.25 | G23: 13782 | H23: United Kingdom
A24: 497935 | B24: 79323W | C24: WHITE CHERRY LIGHTS | D24: 24 | E24: 40224.449 | F24: 5.45 | G24: 13408 | H24: United Kingdom
A25: 502792 | B25: 15044C | C25: PURPLE PAPER PARASOL | D25: 6 | E25: 40263.631 | F25: 2.95 | G25: 14253 | H25: United Kingdom
A26: 521403 | B26: 21179 | D26: 12 | E26: 40427.43 | F26: 1.25 | G26: 12744 | H26: Singapore
A27: 522904 | B27: 72529W | C27: WHITE ADVENT CANDLE | D27: 1 | E27: 40438.531 | F27: 2.12 | G27: 17765 | H27: United Kingdom
A28: 537810 | B28: 22415 | C28: WHITE TISSUE REAM | D28: 3 | E28: 08-12-2010 13:30 | F28: 7.95 | G28: 15032 | H28: United Kingdom
A29: 520505 | B29: 21258 | C29: VICTORIAN SEWING BOX LARGE | D29: 1 | E29: 40416.535 | F29: 12.75 | G29: 17663 | H29: United Kingdom
A30: 533067 | B30: 21122 | C30: SET/10 PINK POLKADOT PARTY CANDLES | D30: 24 | E30: 40497.718 | F30: 1.25 | G30: 17284 | H30: United Kingdom
A31: 523971 | B31: 21009 | C31: ETCHED GLASS STAR TREE DECORATION | D31: 6 | E31: 40447.578 | F31: 1.25 | G31: 15967 | H31: United Kingdom
A32: 499625 | B32: 15056BL | C32: EDWARDIAN PARASOL BLACK | D32: 2 | E32: 40238.551 | F32: 5.95 | G32: 17965 | H32: United Kingdom
A33: 500147 | B33: 47566 | C33: PARTY BUNTING | D33: 8 | E33: 40241.724 | F33: 4.65 | G33: 15812 | H33: United Kingdom
A34: 537421 | B34: 22569 | C34: FELTCRAFT CUSHION BUTTERFLY | D34: 2 | E34: 40518.642 | F34: 3.75 | G34: 17218 | H34: UNITED KINGDOM
A35: 534526 | B35: 21930 | C35: JUMBO STORAGE BAG SKULLS | D35: 10 | E35: 40505.503 | F35: 1.95 | G35: 15384 | H35: United Kingdom
A36: 503164 | B36: 22556 | C36: PLASTERS IN TIN CIRCUS PARADE | D36: 1 | E36: 40267.552 | F36: 1.65 | G36: 17464 | H36: United Kingdom
A37: 528618 | B37: 21499 | C37: BLUE POLKADOT WRAP | D37: 25 | E37: 40473.713 | F37: 0.42 | G37: 13263 | H37: United Kingdom
A38: 505015 | B38: 22196 | C38: SMALL HEART MEASURING SPOONS | D38: 12 | E38: 40287.562 | F38: 0.85 | G38: 14156 | H38: EIRE
A39: 497272 | B39: 84510B | C39: SET OF 4 FAIRY CAKES COASTERS | D39: 10 | E39: 40217.576 | F39: 1.25 | G39: 17160 | H39: United Kingdom
A40: 518480 | B40: 21890 | C40: S/6 WOODEN SKITTLES IN COTTON BAG | D40: 2 | E40: 40399.515 | F40: 2.95 | G40: 16470 | H40: United Kingdom
...

Sheet Clean Data
A1: Invoice | B1: StockCode | C1: Description | D1: Quantity | E1: InvoiceDate | F1: Price | G1: Customer ID | H1: Country | I1: Revenue
A2: 528386 | B2: 22318 | C2: FIVE HEART HANGING DECORATION | D2: 6 | E2: 40472.772 | F2: 2.95 | G2: 14911 | H2: Eire | I2: =(D2 *F2) -> 17.7
A3: 498594 | B3: 21173 | C3: LOO ROLL METAL SIGN | D3: 1 | E3: 40230.658 | F3: 1.65 | G3: 16797 | H3: United Kingdom | I3: =(D3 *F3) -> 1.65
A4: 503245 | B4: 21777 | C4: RECIPE BOX WITH METAL HEART | D4: 2 | E4: 40268.411 | F4: 7.95 | G4: 15216 | H4: United Kingdom | I4: =(D4 *F4) -> 15.9
A5: 505756 | B5: 84836 | C5: ZINC METAL HEART DECORATION | D5: 12 | E5: 40294.408 | F5: 1.25 | G5: 14677 | H5: United Kingdom | I5: =(D5 *F5) -> 15
A6: 496975 | B6: 21559 | C6: STRAWBERRY LUNCHBOX WITH CUTLERY | D6: 6 | E6: 40214.385 | F6: 2.55 | G6: 12712 | H6: Germany | I6: =(D6 *F6) -> 15.3
A7: 491584 | B7: 85107 | C7: CUT GLASS T-LIGHT HOLDER OCTAGON | D7: 12 | E7: 40158.538 | F7: 2.55 | G7: 12854 | H7: United Kingdom | I7: =(D7 *F7) -> 30.6
A8: 516478 | B8: 22575 | C8: METAL MERRY CHRISTMAS WREATH | D8: 1 | E8: 40379.722 | F8: 1.95 | G8: 17576 | H8: United Kingdom | I8: =(D8 *F8) -> 1.95
A9: 502588 | B9: 22083 | C9: PAPER CHAIN KIT RETRO SPOT | D9: 2 | E9: 40262.53 | F9: 2.95 | G9: 16550 | H9: United Kingdom | I9: =(D9 *F9) -> 5.9
A10: 515335 | B10: 85014B | C10: RED/WHITE DOTS RUFFLED UMBRELLA | D10: 1 | E10: 40370.597 | F10: 5.95 | G10: 14606 | H10: United Kingdom | I10: =(D10 *F10) -> 5.95
A11: 525065 | B11: 21156 | C11: RETROSPOT CHILDRENS APRON | D11: 1 | E11: 40454.603 | F11: 1.95 | G11: 16799 | H11: United Kingdom | I11: =(D11 *F11) -> 1.95
A12: 535349 | B12: 84946 | C12: ANTIQUE SILVER TEA GLASS ETCHED | D12: 24 | E12: 40507.703 | F12: 1.25 | G12: 18245 | H12: United Kingdom | I12: =(D12 *F12) -> 30
A13: 521949 | B13: 82484 | C13: WOOD BLACK BOARD ANT WHITE FINISH | D13: 3 | E13: 40430.719 | F13: 6.45 | G13: 15150 | H13: United Kingdom | I13: =(D13 *F13) -> 19.35
A14: 514876 | B14: 22519 | C14: CHILDS GARDEN BRUSH PINK | D14: 36 | E14: 40366.44 | F14: 1.85 | G14: 17511 | H14: United Kingdom | I14: =(D14 *F14) -> 66.6
A15: 521162 | B15: 22561 | C15: WOODEN SCHOOL COLOURING SET | D15: 12 | E15: 40423.599 | F15: 1.65 | G15: 12598 | H15: France | I15: =(D15 *F15) -> 19.8
A16: 506572 | B16: 20798 | C16: CLEAR MILKSHAKE GLASS | D16: 4 | E16: 40298.549 | F16: 2.1 | G16: 16374 | H16: United Kingdom | I16: =(D16 *F16) -> 8.4
A17: 505974 | B17: 48188 | C17: DOOR MAT WELCOME PUPPIES | D17: 1 | E17: 40294.754 | F17: 7.49 | G17: 17449 | H17: United Kingdom | I17: =(D17 *F17) -> 7.49
A18: 491622 | B18: 10125 | C18: MINI FUNKY DESIGN TAPES | D18: 1 | E18: 40158.597 | F18: 0.85 | G18: 13415 | H18: U.K. | I18: =(D18 *F18) -> 0.85
A19: 509982 | B19: 21696 | C19: SMALL SILVER TRELLIS CANDLEPOT | D19: 6 | E19: 40324.603 | F19: 2.95 | G19: 12924 | H19: United Kingdom | I19: =(D19 *F19) -> 17.7
A20: 524611 | B20: 85114B | C20: IVORY ENCHANTED FOREST PLACEMAT | D20: 6 | E20: 40451.401 | F20: 1.65 | G20: 13078 | H20: United Kingdom | I20: =(D20 *F20) -> 9.9
A21: 501906 | B21: 22413 | C21: METAL SIGN TAKE IT OR LEAVE IT | D21: 12 | E21: 40258.668 | F21: 2.95 | G21: 17340 | H21: United Kingdom | I21: =(D21 *F21) -> 35.4
A22: 505708 | B22: 20979 | C22: 36 PENCILS TUBE RED SPOTTY | D22: 1 | E22: 40293.51 | F22: 1.25 | G22: 13782 | H22: United Kingdom | I22: =(D22 *F22) -> 1.25
A23: 497935 | B23: 79323W | C23: WHITE CHERRY LIGHTS | D23: 24 | E23: 40224.449 | F23: 5.45 | G23: 13408 | H23: United Kingdom | I23: =(D23 *F23) -> 130.8
A24: 502792 | B24: 15044C | C24: PURPLE PAPER PARASOL | D24: 6 | E24: 40263.631 | F24: 2.95 | G24: 14253 | H24: United Kingdom | I24: =(D24 *F24) -> 17.7
A25: 522904 | B25: 72529W | C25: WHITE ADVENT CANDLE | D25: 1 | E25: 40438.531 | F25: 2.12 | G25: 17765 | H25: United Kingdom | I25: =(D25 *F25) -> 2.12
A26: 537810 | B26: 22415 | C26: WHITE TISSUE REAM | D26: 3 | E26: 40402.562 | F26: 7.95 | G26: 15032 | H26: United Kingdom | I26: =(D26 *F26) -> 23.85
A27: 520505 | B27: 21258 | C27: VICTORIAN SEWING BOX LARGE | D27: 1 | E27: 40416.535 | F27: 12.75 | G27: 17663 | H27: United Kingdom | I27: =(D27 *F27) -> 12.75
A28: 533067 | B28: 21122 | C28: SET/10 PINK POLKADOT PARTY CANDLES | D28: 24 | E28: 40497.718 | F28: 1.25 | G28: 17284 | H28: United Kingdom | I28: =(D28 *F28) -> 30
A29: 523971 | B29: 21009 | C29: ETCHED GLASS STAR TREE DECORATION | D29: 6 | E29: 40447.578 | F29: 1.25 | G29: 15967 | H29: United Kingdom | I29: =(D29 *F29) -> 7.5
A30: 499625 | B30: 15056BL | C30: EDWARDIAN PARASOL BLACK | D30: 2 | E30: 40238.551 | F30: 5.95 | G30: 17965 | H30: United Kingdom | I30: =(D30 *F30) -> 11.9
A31: 500147 | B31: 47566 | C31: PARTY BUNTING | D31: 8 | E31: 40241.724 | F31: 4.65 | G31: 15812 | H31: United Kingdom | I31: =(D31 *F31) -> 37.2
A32: 537421 | B32: 22569 | C32: FELTCRAFT CUSHION BUTTERFLY | D32: 2 | E32: 40518.642 | F32: 3.75 | G32: 17218 | H32: United Kingdom | I32: =(D32 *F32) -> 7.5
A33: 534526 | B33: 21930 | C33: JUMBO STORAGE BAG SKULLS | D33: 10 | E33: 40505.503 | F33: 1.95 | G33: 15384 | H33: United Kingdom | I33: =(D33 *F33) -> 19.5
A34: 503164 | B34: 22556 | C34: PLASTERS IN TIN CIRCUS PARADE | D34: 1 | E34: 40267.552 | F34: 1.65 | G34: 17464 | H34: United Kingdom | I34: =(D34 *F34) -> 1.65
A35: 528618 | B35: 21499 | C35: BLUE POLKADOT WRAP | D35: 25 | E35: 40473.713 | F35: 0.42 | G35: 13263 | H35: United Kingdom | I35: =(D35 *F35) -> 10.5
A36: 505015 | B36: 22196 | C36: SMALL HEART MEASURING SPOONS | D36: 12 | E36: 40287.562 | F36: 0.85 | G36: 14156 | H36: Eire | I36: =(D36 *F36) -> 10.2
A37: 497272 | B37: 84510B | C37: SET OF 4 FAIRY CAKES COASTERS | D37: 10 | E37: 40217.576 | F37: 1.25 | G37: 17160 | H37: United Kingdom | I37: =(D37 *F37) -> 12.5
A38: 518480 | B38: 21890 | C38: S/6 WOODEN SKITTLES IN COTTON BAG | D38: 2 | E38: 40399.515 | F38: 2.95 | G38: 16470 | H38: United Kingdom | I38: =(D38 *F38) -> 5.9
A39: 508593 | B39: 21900 | C39: KEY FOB , SHED | D39: 24 | E39: 40315.504 | F39: 0.65 | G39: 13488 | H39: United Kingdom | I39: =(D39 *F39) -> 15.6
A40: 505615 | B40: 20712 | C40: JUMBO BAG WOODLAND ANIMALS | D40: 10 | E40: 40291.534 | F40: 1.95 | G40: 15288 | H40: United Kingdom | I40: =(D40 *F40) -> 19.5
...

Sheet Task 2 Analysis
A1: SECTION 4: REVENUE BY COUNTRY
A2: UNITED KINGDOM
A4: SECTION 5: TRANSACTION BY COUNTRY
A5: UNITED KINGDOM
A7: SECTION 6: AVERAGE REVENUE BY COUNTRY
A8: EIRE
A10: SECTION 7: PIVOT TABLE 1
A11: UNITED KINGDOM
A12: DENMARK
A13: NETHERLANDS
A14: EIRE
A15: FRANCE
... A25: 5. small number of product generated large proportion of the total revenue

Sheet Revenue by Country
A3: Row Labels | B3: Sum of Revenue
A4: United Kingdom | B4: 16714.89
A5: Denmark | B5: 1083.6
A6: Netherlands | B6: 872.13
A7: Eire | B7: 842
A8: France | B8: 735.76
A9: Germany | B9: 466.5
A10: Sweden | B10: 155.64
A11: Portugal | B11: 129.3
A12: Japan | B12: 127.5
A13: Un Ited Kingdom | B13: 71.25
A14: Channel Islands | B14: 68.98
A15: Belgium | B15: 64.5
... A27: Grand Total | B27: 21603.28

Sheet Product Revenue
A3: Row Labels | B3: Sum of Revenue
A4: ASSORTED FARMYARD ANIMALS IN BUCKET | B4: 993.6
A5: GOLD WINE GLASS | B5: 976.32
A6: RUSTIC WOODEN CABINET, GLASS DOORS | B6: 573.92
A7: CHILDS BREAKFAST SET CIRCUS PARADE | B7: 397.8
A8: JUMBO SHOPPER VINTAGE RED PAISLEY | B8: 388.5
A9: EDWARDIAN PARASOL BLACK | B9: 362.45
A10: RECIPE BOX WITH METAL HEART | B10: 349.5
A11: BLUE POLKADOT PUDDING BOWL | B11: 324.48
A12: SET/10 RED SPOTTY PARTY CANDLES | B12: 305.28
A13: ROUND SNACK BOXES SET OF 4 FRUITS | B13: 244.8
A14: WHITE HANGING HEART T-LIGHT HOLDER | B14: 240.9
A15: RETROSPOT HEART HOT WATER BOTTLE | B15: 204
... A726: Grand Total | B726: 21603.28

Sheet README
A1: Country | B1: Total Revenue | C1: Number of Transaction | D1: Average Revenue
A2: Eire | B2: =SUMIF('Clean Data'!H:H,"Eire", 'Clean Data'!I:I) -> 842 | C2: =COUNTIF('Clean Data'!H:H,"Eire") -> 18 | D2: =AVERAGEIF('Clean Data'!H:H,"Eire", 'Clean Data'!I:I) -> 46.777778
A3: United Kingdom | B3: =SUMIF('Clean Data'!H:H,"United Kingdom", 'Clean Data'!I:I) -> 16714.89 | C3: =COUNTIF('Clean Data'!H:H,"United Kingdom") -> 876 | D3: =AVERAGEIF('Clean Data'!H:H,"United Kingdom", 'Clean Data'!I:I) -> 19.080925
A4: Germany | B4: =SUMIF('Clean Data'!H:H,"Germany", 'Clean Data'!I:I) -> 466.5 | C4: =COUNTIF('Clean Data'!H:H,"Germany") -> 19 | D4: =AVERAGEIF('Clean Data'!H:H,"Germany", 'Clean Data'!I:I) -> 24.552632
A5: France | B5: =SUMIF('Clean Data'!H:H,"France", 'Clean Data'!I:I) -> 735.76 | C5: =COUNTIF('Clean Data'!H:H,"France") -> 19 | D5: =AVERAGEIF('Clean Data'!H:H,"France", 'Clean Data'!I:I) -> 38.724211
A6: Belgium | B6: =SUMIF('Clean Data'!H:H,"Belgium", 'Clean Data'!I:I) -> 64.5 | C6: =COUNTIF('Clean Data'!H:H,"Belgium") -> 2 | D6: =AVERAGEIF('Clean Data'!H:H,"Belgium", 'Clean Data'!I:I) -> 32.25
